2025-09-03 11:54:19,908 - emsawd.core.logging_config - INFO - Logging configured successfully.
2025-09-03 11:54:19,909 - emsawd.core.logging_config - INFO - Log file created at: logs\historic_weather_20250903_115419.log
2025-09-03 11:54:19,909 - root - INFO - Application starting up.
2025-09-03 11:54:20,414 - root - INFO - Main window shown. Starting event loop.
2025-09-03 11:55:06,939 - emsawd.repositories.geocoding_repository - INFO - Requesting coordinates for 'durban' from https://geocoding-api.open-meteo.com/v1/search
2025-09-03 11:55:11,000 - emsawd.repositories.geocoding_repository - INFO - API response status: 200
2025-09-03 11:55:11,000 - emsawd.repositories.geocoding_repository - INFO - Successfully found coordinates for 'durban': (-29.8579, 31.0292)
2025-09-03 11:55:11,002 - emsawd.repositories.pirate_weather_repository - INFO - Requesting Pirate Weather for 2024-08-27 at lat=-29.8579, lon=31.0292
2025-09-03 11:55:13,284 - emsawd.repositories.pirate_weather_repository - ERROR - Network error for 2024-08-27: 401 Client Error: Unauthorized for url: https://timemachine.pirateweather.net/forecast/free/-29.8579,31.0292,1724752800
Traceback (most recent call last):
  File "C:\Users\User\OneDrive\Documents\GitHub\enhanced-multi-service-aggregated-weather-data\emsawd\repositories\pirate_weather_repository.py", line 46, in get_historical_weather
    response.raise_for_status()
  File "C:\Users\User\OneDrive\Documents\GitHub\enhanced-multi-service-aggregated-weather-data\.venv\Lib\site-packages\requests\models.py", line 1026, in raise_for_status
    raise HTTPError(http_error_msg, response=self)
requests.exceptions.HTTPError: 401 Client Error: Unauthorized for url: https://timemachine.pirateweather.net/forecast/free/-29.8579,31.0292,1724752800
2025-09-03 11:55:13,288 - emsawd.repositories.pirate_weather_repository - INFO - Requesting Pirate Weather for 2023-08-27 at lat=-29.8579, lon=31.0292
2025-09-03 11:55:14,268 - emsawd.repositories.pirate_weather_repository - ERROR - Network error for 2023-08-27: 401 Client Error: Unauthorized for url: https://timemachine.pirateweather.net/forecast/free/-29.8579,31.0292,1693130400
Traceback (most recent call last):
  File "C:\Users\User\OneDrive\Documents\GitHub\enhanced-multi-service-aggregated-weather-data\emsawd\repositories\pirate_weather_repository.py", line 46, in get_historical_weather
    response.raise_for_status()
  File "C:\Users\User\OneDrive\Documents\GitHub\enhanced-multi-service-aggregated-weather-data\.venv\Lib\site-packages\requests\models.py", line 1026, in raise_for_status
    raise HTTPError(http_error_msg, response=self)
requests.exceptions.HTTPError: 401 Client Error: Unauthorized for url: https://timemachine.pirateweather.net/forecast/free/-29.8579,31.0292,1693130400
2025-09-03 11:55:14,271 - emsawd.repositories.pirate_weather_repository - INFO - Requesting Pirate Weather for 2022-08-27 at lat=-29.8579, lon=31.0292
2025-09-03 11:55:15,166 - emsawd.repositories.pirate_weather_repository - ERROR - Network error for 2022-08-27: 401 Client Error: Unauthorized for url: https://timemachine.pirateweather.net/forecast/free/-29.8579,31.0292,1661594400
Traceback (most recent call last):
  File "C:\Users\User\OneDrive\Documents\GitHub\enhanced-multi-service-aggregated-weather-data\emsawd\repositories\pirate_weather_repository.py", line 46, in get_historical_weather
    response.raise_for_status()
  File "C:\Users\User\OneDrive\Documents\GitHub\enhanced-multi-service-aggregated-weather-data\.venv\Lib\site-packages\requests\models.py", line 1026, in raise_for_status
    raise HTTPError(http_error_msg, response=self)
requests.exceptions.HTTPError: 401 Client Error: Unauthorized for url: https://timemachine.pirateweather.net/forecast/free/-29.8579,31.0292,1661594400
2025-09-03 11:55:27,064 - root - INFO - Application exiting with code 0.
